Workbook

Sheet Priority & Sequence
A1: Seq # | B1: Priority | C1: Target Phase / Sprint | D1: Processor ID | E1: Step Processor Name | F1: Family Code | G1: Family Name | H1: Current Status | I1: Effort | J1: Assigned Owner / Team | K1: Target Release / Date | L1: Key Dependencies & Tech Seam | M1: Business Impact & Value
A2: 1 | B2: P0 | C2: Phase 1: Cloud & Lake | D2: SP-ACQ-06 | E2: AWS S3 object ingest | F2: ACQ | G2: Collectors & Ingestion | H2: Planned | I2: Med | L2: AWS SDK v2, `inspecto-connectors` | M2: Cloud file ingestion baseline; table stakes for AWS environments
A3: 2 | B3: P0 | C3: Phase 1: Cloud & Lake | D3: SP-ACQ-07 | E3: Azure Blob & ADLS Gen2 ingest | F3: ACQ | G3: Collectors & Ingestion | H3: Partial | I3: Low | L3: Azure Blob SDK, directory recursion test | M3: Quick win: verify ADLS Gen2 hierarchy on existing Azure connector
A4: 3 | B4: P0 | C4: Phase 1: Core Formats | D4: SP-PRS-05 | E4: XML / XPath / DOM unpacker | F4: PRS | G4: Extraction & Format Parsers | H4: Partial | I4: Med | L4: StAX / VTD-XML, `parser.xml` node | M4: Closes major enterprise ingestion gap beyond existing tree plugin
A5: 4 | B5: P0 | C5: Phase 1: Core Formats | D5: SP-PRS-14 | E5: Apache Avro binary decoder | F5: PRS | G5: Extraction & Format Parsers | H5: Planned | I5: Med | L5: DuckDB Avro scanner / Apache Avro | M5: High-speed ingestion for Kafka dumps and Hadoop migration feeds
A6: 5 | B6: P0 | C6: Phase 1: Core Formats | D6: SP-ACQ-05 | E6: Multi-sheet Excel workbook ingest | F6: ACQ | G6: Collectors & Ingestion | H6: Partial | I6: Low | L6: Apache POI / DuckDB Excel metadata | M6: Quick win: sheet discovery wrapper feeding existing `parser.xlsx`
A7: 6 | B7: P0 | C7: Phase 1: Advanced ETL | D7: SP-XFM-07 | E7: Dynamic pivot / transpose | F7: XFM | G7: Transformers & Dimensional Modeling | H7: Planned | I7: Low | L7: DuckDB `PIVOT` syntax lowerer | M7: Critical for financial, tabular, and time-matrix reporting
A8: 7 | B8: P0 | C8: Phase 1: Advanced ETL | D8: SP-XFM-08 | E8: Unpivot / column flattener | F8: XFM | G8: Transformers & Dimensional Modeling | H8: Planned | I8: Low | L8: DuckDB `UNPIVOT` syntax lowerer | M8: Normalizes wide survey/Excel tables into tidy relational rows
A9: 8 | B9: P0 | C9: Phase 1: Quality & Gov | D9: SP-DQ-06 | E9: Schema drift & new-field detector | F9: DQ | G9: Data Quality, Validation & Cleansing | H9: Partial | I9: Med | L9: Schema comparator, drift event bridge | M9: Prevents silent data corruption when upstream providers add fields
A10: 9 | B10: P0 | C10: Phase 1: Quality & Gov | D10: SP-SNK-15 | E10: Dead-letter queue (DLQ) | F10: SNK | G10: Sinks, Storage & Destinations | H10: Planned | I10: Med | L10: DLQ store layout, error payload wrapper | M10: Safe landing for poisoned records without failing batch jobs
A11: 10 | B11: P1 | C11: Phase 2: Streaming | D11: SP-ACQ-09 | E11: Apache Kafka consumer | F11: ACQ | G11: Collectors & Ingestion | H11: Partial | I11: Med | L11: Kafka consumer group, file buffer | M11: Connects event-driven Kafka topics into micro-batch pipelines
A12: 11 | B12: P1 | C12: Phase 2: Streaming | D12: SP-SNK-11 | E12: Apache Kafka topic producer | F12: SNK | G12: Sinks, Storage & Destinations | H12: Planned | I12: Med | L12: Kafka Producer client, JSON/Avro encoder | M12: Enables reverse-ETL streaming into downstream consumer buses
A13: 12 | B13: P1 | C13: Phase 2: Lakehouse | D13: SP-ACQ-15 | E13: Delta Lake table reader | F13: ACQ | G13: Collectors & Ingestion | H13: Planned | I13: High | L13: `delta-kernel-java` / DuckDB Delta ext | M13: Ingests versioned Delta tables directly from Databricks / S3
... A86: 85 | B86: N/A | C86: Maintain Legacy | D86: SP-SNK-04 | E86: Derived view | F86: SNK | G86: Sinks, Storage & Destinations | H86: Partial | I86: Low | L86: *Superseded by Datasets/Views* | M86: Grandfathered type maintained for backwards compatibility

Sheet All 119 Processors
A1: Board ID | B1: Catalog ID | C1: Emoji | D1: Processor Label | E1: Family Code | F1: Family Name | G1: Status | H1: Maps To | I1: Capability / Seam | J1: Addable in UI | K1: Notes & Gaps
A2: SP-ACQ-01 | B2: acquisition.file.local | C2: 📁 | D2: Local / NFS directory watcher | E2: ACQ | F2: Collectors & Ingestion | G2: Delivered | H2: acquisition | I2: — | J2: Yes | K2: LocalFileSystemConnector — the default collector
A3: SP-ACQ-02 | B3: acquisition.file.sftp | C3: 🔒 | D3: SFTP / FTPS remote ingest | E3: ACQ | F3: Collectors & Ingestion | G3: Delivered | H3: acquisition | I3: — | J3: Yes | K3: inspecto-connectors (sftp, ftps; key auth, bastion tunnel, host-key pinning)
A4: SP-ACQ-03 | B4: acquisition.db.jdbc | C4: 🗄️ | D4: JDBC / SQL query batch reader | E4: ACQ | F4: Collectors & Ingestion | G4: Delivered | H4: acquisition | I4: — | J4: Yes | K4: the db-export connector (`connector: db`, watermark column)
A5: SP-ACQ-04 | B5: acquisition.dataset | C5: 🧱 | D5: Dataset entry (re-ingest a registered Dataset) | E5: ACQ | F5: Collectors & Ingestion | G5: Delivered | H5: acquisition | I5: — | J5: Yes | K5: UI-S7: `connector: dataset` + `on:dataset` trigger
A6: SP-ACQ-05 | B6: acquisition.file.excel | C6: 📑 | D6: Multi-sheet Excel workbook ingest | E6: ACQ | F6: Collectors & Ingestion | G6: Partial | H6: parser.xlsx | I6: — | J6: Yes | K6: the xlsx PARSER is delivered; per-sheet workbook fan-out as an acquisition is not
A7: SP-ACQ-06 | B7: acquisition.file.s3 | C7: ☁️ | D7: AWS S3 object ingest | E7: ACQ | F7: Collectors & Ingestion | G7: Planned | H7: — | I7: — | J7: No
A8: SP-ACQ-07 | B8: acquisition.file.azure | C8: 🌐 | D8: Azure Blob & ADLS Gen2 ingest | E8: ACQ | F8: Collectors & Ingestion | G8: Partial | H8: acquisition | I8: — | J8: Yes | K8: Connection kind exists (azure blob connector); ADLS Gen2 semantics not proven
A9: SP-ACQ-08 | B9: acquisition.file.gcs | C9: 🪣 | D9: Google Cloud Storage ingest | E9: ACQ | F9: Collectors & Ingestion | G9: Planned | H9: — | I9: — | J9: No
A10: SP-ACQ-09 | B10: acquisition.stream.kafka | C10: 📤 | D10: Apache Kafka consumer | E10: ACQ | F10: Collectors & Ingestion | G10: Partial | H10: acquisition | I10: — | J10: Yes | K10: Connection kind exists (kafka); consumer-group ingest as a Collector not proven
A11: SP-ACQ-10 | B11: acquisition.stream.pulsar | C11: 📨 | D11: Apache Pulsar consumer | E11: ACQ | F11: Collectors & Ingestion | G11: Planned | H11: — | I11: — | J11: No
A12: SP-ACQ-11 | B12: acquisition.stream.kinesis | C12: 📬 | D12: AWS Kinesis / SQS ingest | E12: ACQ | F12: Collectors & Ingestion | G12: Planned | H12: — | I12: — | J12: No
A13: SP-ACQ-12 | B13: acquisition.stream.rabbitmq | C13: 🐰 | D13: RabbitMQ AMQP subscriber | E13: ACQ | F13: Collectors & Ingestion | G13: Planned | H13: — | I13: — | J13: No
A14: SP-ACQ-13 | B14: acquisition.stream.mqtt | C14: 📡 | D14: MQTT IoT telemetry ingest | E14: ACQ | F14: Collectors & Ingestion | G14: Planned | H14: — | I14: — | J14: No
A15: SP-ACQ-14 | B15: acquisition.cdc.debezium | C15: 🔄 | D15: Change Data Capture (Debezium) | E15: ACQ | F15: Collectors & Ingestion | G15: Planned | H15: — | I15: — | J15: No
A16: SP-ACQ-15 | B16: acquisition.lake.delta | C16: 💾 | D16: Delta Lake table reader | E16: ACQ | F16: Collectors & Ingestion | G16: Planned | H16: — | I16: — | J16: No
A17: SP-ACQ-16 | B17: acquisition.lake.iceberg | C17: 🧊 | D17: Apache Iceberg table ingest | E17: ACQ | F17: Collectors & Ingestion | G17: Planned | H17: — | I17: — | J17: No
A18: SP-ACQ-17 | B18: acquisition.db.cloud | C18: ❄️ | D18: Snowflake / BigQuery ingest | E18: ACQ | F18: Collectors & Ingestion | G18: Planned | H18: — | I18: — | J18: No
A19: SP-ACQ-18 | B19: acquisition.api.rest | C19: 🌐 | D19: REST API poller & paged ingest | E19: ACQ | F19: Collectors & Ingestion | G19: Planned | H19: — | I19: — | J19: No
A20: SP-ACQ-19 | B20: acquisition.api.webhook | C20: 🪝 | D20: HTTP webhook listener endpoint | E20: ACQ | F20: Collectors & Ingestion | G20: Planned | H20: — | I20: — | J20: No
A21: SP-ACQ-20 | B21: acquisition.api.grpc | C21: 🔌 | D21: gRPC stream receiver | E21: ACQ | F21: Collectors & Ingestion | G21: Planned | H21: — | I21: — | J21: No
A22: SP-PRS-01 | B22: parser.delimited | C22: 📄 | D22: Delimited / CSV / TSV / PSV parser | E22: PRS | F22: Extraction & Format Parsers | G22: Delivered | H22: parser.delimited | I22: — | J22: Yes
A23: SP-PRS-02 | B23: parser.fixedwidth | C23: 📦 | D23: Fixed-width column slicer | E23: PRS | F23: Extraction & Format Parsers | G23: Delivered | H23: parser.fixedwidth | I23: — | J23: Yes | K23: text (`record: line`) and fixed-length binary (`record: bytes`)
A24: SP-PRS-03 | B24: parser.json | C24: 🧬 | D24: JSON object & JSON Lines (NDJSON) parser | E24: PRS | F24: Extraction & Format Parsers | G24: Delivered | H24: parser.json | I24: — | J24: Yes
A25: SP-PRS-04 | B25: parser.excel | C25: 📑 | D25: Excel workbook parser | E25: PRS | F25: Extraction & Format Parsers | G25: Delivered | H25: parser.xlsx | I25: — | J25: Yes | K25: needs the DuckDB `excel` extension in the bundle (multiformat X1)
A26: SP-PRS-05 | B26: parser.xml | C26: 📑 | D26: XML / XPath / DOM unpacker | E26: PRS | F26: Extraction & Format Parsers | G26: Partial | H26: parser.plugin | I26: — | J26: Yes | K26: tree→segments bridge ships XML ingests; no XPath selector grammar yet
A27: SP-PRS-06 | B27: parser.asn1.ber | C27: 📡 | D27: ASN.1 BER telecom CDR decoder | E27: PRS | F27: Extraction & Format Parsers | G27: Delivered | H27: — | I27: parser.asn1 | J27: No | K27: asn-parser reactor (decoders, vendor plugins)
A28: SP-PRS-07 | B28: parser.pattern.regex | C28: 🔎 | D28: Named-group regex extractor | E28: PRS | F28: Extraction & Format Parsers | G28: Delivered | H28: parser.text_regex | I28: — | J28: Yes
A29: SP-PRS-08 | B29: parser.plugin | C29: 🧩 | D29: Custom ingester plugin (segments, multi-event) | E29: PRS | F29: Extraction & Format Parsers | G29: Delivered | H29: parser.plugin | I29: — | J29: Yes | K29: ParserPlugin SPI; `segments: {CALL, SMS}`
A30: SP-PRS-09 | B30: parser.keyvalue | C30: 🏷️ | D30: Key-value / logfmt parser | E30: PRS | F30: Extraction & Format Parsers | G30: Planned | H30: — | I30: — | J30: No
A31: SP-PRS-10 | B31: parser.yaml | C31: 📜 | D31: YAML document slicer | E31: PRS | F31: Extraction & Format Parsers | G31: Planned | H31: — | I31: — | J31: No
A32: SP-PRS-11 | B32: parser.asn1.per | C32: 📜 | D32: ASN.1 PER / XER / DER decoder | E32: PRS | F32: Extraction & Format Parsers | G32: Planned | H32: — | I32: — | J32: No
A33: SP-PRS-12 | B33: parser.mainframe.ebcdic | C33: 📠 | D33: Mainframe EBCDIC & COBOL copybook | E33: PRS | F33: Extraction & Format Parsers | G33: Planned | H33: — | I33: — | J33: No
A34: SP-PRS-13 | B34: parser.binary.protobuf | C34: ⚡ | D34: Protocol Buffers decoder | E34: PRS | F34: Extraction & Format Parsers | G34: Planned | H34: — | I34: — | J34: No
A35: SP-PRS-14 | B35: parser.binary.avro | C35: 🦅 | D35: Apache Avro binary decoder | E35: PRS | F35: Extraction & Format Parsers | G35: Planned | H35: — | I35: — | J35: No
A36: SP-PRS-15 | B36: parser.binary.pcap | C36: 🌐 | D36: PCAP network packet slicer | E36: PRS | F36: Extraction & Format Parsers | G36: Planned | H36: — | I36: — | J36: No
A37: SP-PRS-16 | B37: parser.pattern.grok | C37: 📜 | D37: Grok / Logstash expression matcher | E37: PRS | F37: Extraction & Format Parsers | G37: Planned | H37: — | I37: — | J37: No
A38: SP-PRS-17 | B38: parser.pattern.syslog | C38: 🖥️ | D38: Syslog RFC 5424 / RFC 3164 parser | E38: PRS | F38: Extraction & Format Parsers | G38: Planned | H38: — | I38: — | J38: No
A39: SP-DQ-01 | B39: quality.schema.validator | C39: 🛡️ | D39: Schema registry & structural rejects | E39: DQ | F39: Data Quality, Validation & Cleansing | G39: Delivered | H39: parser | I39: — | J39: No | K39: the declared schema on the Parse Step: typed fields, TRY_CAST at ingest, structural rejects → quarantine. ⛔ Only HALF of the old "Schema validator & type coercion" — coercion as an AUTHORING act folded into `transform.record` (2026-09-04). What cannot fold is the schema CONTRACT: the declared source column + target type are the cast-failure audit's denominator, and `SchemaCompatibility` gates edits to them BACKWARD
A40: SP-DQ-02 | B40: quality.constraint.check | C40: ⚠️ | D40: Constraint & range checker (Expectations) | E40: DQ | F40: Data Quality, Validation & Cleansing | G40: Delivered | H40: — | I40: expectation | J40: No | K40: Expectations evaluated per Dataset (`ExpectationEvaluator`); not a mid-chain step
...

Sheet Dashboard & KPIs
A1: Inspecto Step Processors Portfolio Dashboard
A3: Portfolio Status Summary (All 119 Processors)
A4: Family Code | B4: Family Label | C4: Delivered (✅) | D4: Partial (🟡) | E4: Planned (🔲) | F4: Total Processors | G4: % Delivered
A5: ACQ | B5: Collectors & Ingestion | C5: =COUNTIFS('All 119 Processors'!$E:$E, A5, 'All 119 Processors'!$G:$G, "Delivered") | D5: =COUNTIFS('All 119 Processors'!$E:$E, A5, 'All 119 Processors'!$G:$G, "Partial") | E5: =COUNTIFS('All 119 Processors'!$E:$E, A5, 'All 119 Processors'!$G:$G, "Planned") | F5: =SUM(C5:E5) | G5: =C5/F5
A6: PRS | B6: Extraction & Format Parsers | C6: =COUNTIFS('All 119 Processors'!$E:$E, A6, 'All 119 Processors'!$G:$G, "Delivered") | D6: =COUNTIFS('All 119 Processors'!$E:$E, A6, 'All 119 Processors'!$G:$G, "Partial") | E6: =COUNTIFS('All 119 Processors'!$E:$E, A6, 'All 119 Processors'!$G:$G, "Planned") | F6: =SUM(C6:E6) | G6: =C6/F6
A7: DQ | B7: Data Quality, Validation & Cleansing | C7: =COUNTIFS('All 119 Processors'!$E:$E, A7, 'All 119 Processors'!$G:$G, "Delivered") | D7: =COUNTIFS('All 119 Processors'!$E:$E, A7, 'All 119 Processors'!$G:$G, "Partial") | E7: =COUNTIFS('All 119 Processors'!$E:$E, A7, 'All 119 Processors'!$G:$G, "Planned") | F7: =SUM(C7:E7) | G7: =C7/F7
A8: XFM | B8: Transformers & Dimensional Modeling | C8: =COUNTIFS('All 119 Processors'!$E:$E, A8, 'All 119 Processors'!$G:$G, "Delivered") | D8: =COUNTIFS('All 119 Processors'!$E:$E, A8, 'All 119 Processors'!$G:$G, "Partial") | E8: =COUNTIFS('All 119 Processors'!$E:$E, A8, 'All 119 Processors'!$G:$G, "Planned") | F8: =SUM(C8:E8) | G8: =C8/F8
A9: BI | B9: Analytics, Time-Series & Semantic Modeling | C9: =COUNTIFS('All 119 Processors'!$E:$E, A9, 'All 119 Processors'!$G:$G, "Delivered") | D9: =COUNTIFS('All 119 Processors'!$E:$E, A9, 'All 119 Processors'!$G:$G, "Partial") | E9: =COUNTIFS('All 119 Processors'!$E:$E, A9, 'All 119 Processors'!$G:$G, "Planned") | F9: =SUM(C9:E9) | G9: =C9/F9
A10: ENR | B10: Enrichment, Entity Resolution & AI/ML | C10: =COUNTIFS('All 119 Processors'!$E:$E, A10, 'All 119 Processors'!$G:$G, "Delivered") | D10: =COUNTIFS('All 119 Processors'!$E:$E, A10, 'All 119 Processors'!$G:$G, "Partial") | E10: =COUNTIFS('All 119 Processors'!$E:$E, A10, 'All 119 Processors'!$G:$G, "Planned") | F10: =SUM(C10:E10) | G10: =C10/F10
A11: CTL | B11: Control, Governance & Sequence Integrity | C11: =COUNTIFS('All 119 Processors'!$E:$E, A11, 'All 119 Processors'!$G:$G, "Delivered") | D11: =COUNTIFS('All 119 Processors'!$E:$E, A11, 'All 119 Processors'!$G:$G, "Partial") | E11: =COUNTIFS('All 119 Processors'!$E:$E, A11, 'All 119 Processors'!$G:$G, "Planned") | F11: =SUM(C11:E11) | G11: =C11/F11
A12: SNK | B12: Sinks, Storage & Destinations | C12: =COUNTIFS('All 119 Processors'!$E:$E, A12, 'All 119 Processors'!$G:$G, "Delivered") | D12: =COUNTIFS('All 119 Processors'!$E:$E, A12, 'All 119 Processors'!$G:$G, "Partial") | E12: =COUNTIFS('All 119 Processors'!$E:$E, A12, 'All 119 Processors'!$G:$G, "Planned") | F12: =SUM(C12:E12) | G12: =C12/F12
A13: TOTAL | B13: All 8 Families | C13: =SUM(C5:C12) | D13: =SUM(D5:D12) | E13: =SUM(E5:E12) | F13: =SUM(F5:F12) | G13: =C13/F13
A16: Pending Processors Priority Distribution (Sheet: Priority & Sequence)
A17: Priority Tier | B17: Definition | C17: Count | D17: % of Pending Backlog
A18: P0 | B18: Critical / Immediate (Phase 1 Baseline & Quick Wins) | C18: =COUNTIF('Priority & Sequence'!$B:$B, A18) | D18: =C18/SUM($C$18:$C$22)
A19: P1 | B19: High Value (Lakehouse, Streaming, Modeling, Security) | C19: =COUNTIF('Priority & Sequence'!$B:$B, A19) | D19: =C19/SUM($C$18:$C$22)
A20: P2 | B20: Medium Value (Multi-Cloud, Advanced Analytics, Quality) | C20: =COUNTIF('Priority & Sequence'!$B:$B, A20) | D20: =C20/SUM($C$18:$C$22)
A21: P3 | B21: Specialized / Niche (Telecom, FinTech, Legacy, AI/ML) | C21: =COUNTIF('Priority & Sequence'!$B:$B, A21) | D21: =C21/SUM($C$18:$C$22)
A22: N/A | B22: Internal Engine Core or Superseded Capabilities | C22: =COUNTIF('Priority & Sequence'!$B:$B, A22) | D22: =C22/SUM($C$18:$C$22)
A23: TOTAL | B23: Total Pending Backlog | C23: =SUM(C18:C22) | D23: 100.0%
